{
  "comments": [
    {
      "key": {
        "uuid": "9f560f44_4b497364",
        "filename": "/COMMIT_MSG",
        "patchSetId": 1
      },
      "lineNbr": 9,
      "author": {
        "id": 5263
      },
      "writtenOn": "2020-10-03T15:52:47Z",
      "side": 1,
      "message": "The problem had nothing to do with CI servers or a PyPI cache. They were due to the Fastly CDN used by PyPI sometimes pulling incomplete indices from a fallback server which lacked requires-python metadata when they had trouble reaching PyPI\u0027s primary site. The PyPI administrators are aware of the issue and have taken steps to address it.",
      "revId": "1b83baef91ba861a91ed0ff264290219193986f8",
      "serverId": "4a232e18-c5a9-48ee-94c0-e04e7cca6543",
      "unresolved": false
    },
    {
      "key": {
        "uuid": "9f560f44_906c5308",
        "filename": "/COMMIT_MSG",
        "patchSetId": 1
      },
      "lineNbr": 9,
      "author": {
        "id": 16688
      },
      "writtenOn": "2020-10-05T06:59:06Z",
      "side": 1,
      "message": "That was the information I had at this time.",
      "parentUuid": "9f560f44_4b497364",
      "revId": "1b83baef91ba861a91ed0ff264290219193986f8",
      "serverId": "4a232e18-c5a9-48ee-94c0-e04e7cca6543",
      "unresolved": false
    }
  ]
}