{
  "comments": [
    {
      "unresolved": false,
      "key": {
        "uuid": "36e7f082_72a72a46",
        "filename": "/PATCHSET_LEVEL",
        "patchSetId": 1
      },
      "lineNbr": 0,
      "author": {
        "id": 5314
      },
      "writtenOn": "2022-04-20T12:54:38Z",
      "side": 1,
      "message": "recheck tempest-full-py3 - tempest.api.volume.test_volumes_actions.VolumesActionsTest.test_volume_upload : ERROR cinder.volume.manager [None req-c50b7a30-37fd-4dcf-a902-5bce519fc97b tempest-VolumesActionsTest-311132640 None] Upload volume to image encountered an error (image-id: 43190406-5c79-4b6e-baa0-a9c822bc833a).: cinder.exception.GlanceConnectionFailed: Connection to glance failed: Error finding address for https://10.176.196.145/image/v2/images/43190406-5c79-4b6e-baa0-a9c822bc833a/file: Unable to establish connection to https://10.176.196.145/image/v2/images/43190406-5c79-4b6e-baa0-a9c822bc833a/file: (104, \u0027ECONNRESET\u0027)",
      "revId": "4da98ee6d48c159be8d48923f189dd923bb17e31",
      "serverId": "4a232e18-c5a9-48ee-94c0-e04e7cca6543"
    },
    {
      "unresolved": false,
      "key": {
        "uuid": "14948d2d_85653e7e",
        "filename": "/PATCHSET_LEVEL",
        "patchSetId": 1
      },
      "lineNbr": 0,
      "author": {
        "id": 5314
      },
      "writtenOn": "2022-04-20T16:21:51Z",
      "side": 1,
      "message": "LGTM.",
      "revId": "4da98ee6d48c159be8d48923f189dd923bb17e31",
      "serverId": "4a232e18-c5a9-48ee-94c0-e04e7cca6543"
    }
  ]
}