{
  "comments": [
    {
      "key": {
        "uuid": "5fc1f717_54a7c6a8",
        "filename": "/COMMIT_MSG",
        "patchSetId": 1
      },
      "lineNbr": 15,
      "author": {
        "id": 6873
      },
      "writtenOn": "2019-04-01T16:27:33Z",
      "side": 1,
      "message": "This might fix this bug but it\u0027s not really backportable (maybe it is, IDK), so we might want something in between that does a retry in check_python3_support_for_package_remote if it gets empty or partial results.",
      "revId": "60b672a6e5d6c7a36cbd0b8d139ff109bee7a095",
      "serverId": "4a232e18-c5a9-48ee-94c0-e04e7cca6543",
      "unresolved": false
    }
  ]
}