{
  "comments": [
    {
      "unresolved": false,
      "key": {
        "uuid": "1aa77dc5_bdee6de8",
        "filename": "/PATCHSET_LEVEL",
        "patchSetId": 2
      },
      "lineNbr": 0,
      "author": {
        "id": 17685
      },
      "writtenOn": "2025-05-19T08:02:51Z",
      "side": 1,
      "message": "recheck - neutron-linuxbridge-tempest failed why fetching get-pip.py, however the file is reachable... probably pypa.io glitch :S",
      "revId": "9b875bad906dbb70b10fea585efc89091eef9519",
      "serverId": "4a232e18-c5a9-48ee-94c0-e04e7cca6543"
    }
  ]
}